<sdf version='1.7'>
  <model name='boat_1'>
    <link name='hull_1'>
      <inertial>
        <pose>0.055 0 -0.5 0 -0 0</pose>
        <mass>2000</mass>
        <inertia>
          <ixx>5000</ixx>
          <ixy>0</ixy>
          <ixz>0</ixz>
          <iyy>5000</iyy>
          <iyz>0</iyz>
          <izz>5000</izz>
        </inertia>
      </inertial>
      <collision name='hull_1_fixed_joint_lump__hull_collision_collision'>
        <pose>0 0 0 0 -0 0</pose>
        <geometry>
          <box>
            <size>2 1.33 1.7</size>
          </box>
        </geometry>
      </collision>
      <collision name='hull_1_fixed_joint_lump__stabilizer_left_collision_1'>
        <pose>0 1 0 0 -0 0</pose>
        <geometry>
          <box>
            <size>1 0.1 0.1</size>
          </box>
        </geometry>
      </collision>
      <collision name='hull_1_fixed_joint_lump__stabilizer_right_collision_2'>
        <pose>0 -1 0 0 -0 0</pose>
        <geometry>
          <box>
            <size>1 0.1 0.1</size>
          </box>
        </geometry>
      </collision>
      <visual name='hull_1_visual'>
        <pose>0 0 0 0 -0 0</pose>
        <geometry>
          <mesh>
            <scale>1 1 1</scale>
            <uri>model://boat_1/meshes/boat.stl</uri>
          </mesh>
        </geometry>
      </visual>
      <velocity_decay>
        <linear>0.1</linear>
        <angular>50</angular>
      </velocity_decay>
    </link>
    <joint name='prop_joint_left' type='revolute'>
      <pose relative_to='hull_1'>-1.1 -0.5 -0.24 0 -0 0</pose>
      <parent>hull_1</parent>
      <child>propeller_left</child>
      <axis>
        <xyz>1 0 0</xyz>
        <limit>
          <lower>-1e+16</lower>
          <upper>1e+16</upper>
        </limit>
        <dynamics>
          <spring_reference>0</spring_reference>
          <spring_stiffness>0</spring_stiffness>
        </dynamics>
      </axis>
    </joint>
    <link name='propeller_left'>
      <pose relative_to='prop_joint_left'>0 0 0 0 -0 0</pose>
      <inertial>
        <pose>0 0 0 0 -0 0</pose>
        <mass>50</mass>
        <inertia>
          <ixx>0.1</ixx>
          <ixy>0</ixy>
          <ixz>0</ixz>
          <iyy>0.1</iyy>
          <iyz>0</iyz>
          <izz>0.1</izz>
        </inertia>
      </inertial>
      <visual name='propeller_left_visual'>
        <pose>0 0 0 0 -0 0</pose>
        <geometry>
          <mesh>
            <scale>1 1 1</scale>
            <uri>model://boat_1/meshes/prop.stl</uri>
          </mesh>
        </geometry>
      </visual>
    </link>
    <joint name='prop_joint_right' type='revolute'>
      <pose relative_to='hull_1'>-1.1 0.5 -0.24 0 -0 0</pose>
      <parent>hull_1</parent>
      <child>propeller_right</child>
      <axis>
        <xyz>-1 0 0</xyz>
        <limit>
          <lower>-1e+16</lower>
          <upper>1e+16</upper>
        </limit>
        <dynamics>
          <spring_reference>0</spring_reference>
          <spring_stiffness>0</spring_stiffness>
        </dynamics>
      </axis>
    </joint>
    <link name='propeller_right'>
      <pose relative_to='prop_joint_right'>0 0 0 0 -0 0</pose>
      <inertial>
        <pose>0 0 0 0 -0 0</pose>
        <mass>50</mass>
        <inertia>
          <ixx>0.1</ixx>
          <ixy>0</ixy>
          <ixz>0</ixz>
          <iyy>0.1</iyy>
          <iyz>0</iyz>
          <izz>0.1</izz>
        </inertia>
      </inertial>
      <visual name='propeller_right_visual'>
        <pose>0 0 0 0 -0 0</pose>
        <geometry>
          <mesh>
            <scale>1 1 1</scale>
            <uri>model://boat_1/meshes/prop.stl</uri>
          </mesh>
        </geometry>
      </visual>
    </link>
    <plugin name='ignition::gazebo::systems::Thruster' filename='libignition-gazebo-thruster-system.so'>
      <joint_name>prop_joint_left</joint_name>
      <thrust_coefficient>0.1</thrust_coefficient>
      <fluid_density>1000</fluid_density>
      <propeller_diameter>0.2</propeller_diameter>
      <velocity_control>1</velocity_control>
      <p_gain>0.1</p_gain>
    </plugin>
    <plugin name='ignition::gazebo::systems::Thruster' filename='libignition-gazebo-thruster-system.so'>
      <joint_name>prop_joint_right</joint_name>
      <thrust_coefficient>0.1</thrust_coefficient>
      <fluid_density>1000</fluid_density>
      <propeller_diameter>0.2</propeller_diameter>
      <velocity_control>1</velocity_control>
      <p_gain>0.1</p_gain>
    </plugin>
    <static>0</static>
    <plugin name='ignition::gazebo::systems::Hydrodynamics' filename='libignition-gazebo-hydrodynamics-system.so'>
      <link_name>hull_1</link_name>
      <linear_drag_coefficients>1 50 50</linear_drag_coefficients>
      <angular_drag_coefficients>5000 5000 5000</angular_drag_coefficients>

    </plugin>

<!-- Joint Controllers -->

<plugin filename="libignition-gazebo-joint-controller-system.so"
        name="ignition::gazebo::systems::JointController">

  <joint_name>prop_joint_left</joint_name>
  <joint_name>prop_joint_right</joint_name>

</plugin>

  </model>
</sdf>
