<?xml version="1.0" ?>
<robot name="boat_1">
  <!-- ROOT BASE LINK -->
  <link name="base_link">
    <visual>
      <geometry>
        <box size="0.01 0.01 0.01"/>
      </geometry>
      <material name="invisible">
        <color rgba="0 0 0 0"/>
      </material>
    </visual>
  </link>
  <joint name="base_to_hull" type="fixed">
    <parent link="base_link"/>
    <child link="hull_1"/>
    <origin rpy="0 0 0" xyz="0 0 0"/>
  </joint>

  <!-- HULL LINK-->
  <link name="hull_1">
    <inertial>
      <origin rpy="0 0 0" xyz="0.055 0 -0.5"/>
      <mass value="2000"/>
      <inertia ixx="5000" ixy="0" ixz="0" iyy="5000" iyz="0" izz="5000"/>
    </inertial>
    <collision>
      <geometry>
        <box size="2 1.33 1.7"/>
      </geometry>
    </collision>
    <visual>
      <geometry>
        <mesh filename="package://boat_1/meshes/boat.stl"/>
      </geometry>
    </visual>
  </link>
  <!-- LiDAR LINK -->
  <link name="lidar_link">
    <inertial>
      <mass value="0.5"/>
      <inertia ixx="0.001" ixy="0" ixz="0" iyy="0.001" iyz="0" izz="0.001"/>
    </inertial>
    <visual>
      <geometry>
        <cylinder length="0.15" radius="0.12"/>
      </geometry>
      <material name="blue">
        <color rgba="0 0 1 1"/>
      </material>
    </visual>
    <collision>
      <geometry>
        <cylinder length="0.15" radius="0.12"/>
      </geometry>
    </collision>
  </link>
  <joint name="lidar_joint" type="fixed">
    <parent link="hull_1"/>
    <child link="lidar_link"/>
    <origin rpy="0 0 0" xyz="0.75 0.0 0.960"/>
  </joint>

  <!-- PROPELLERS -->
  <link name="propeller_left">
    <inertial>
      <mass value="50"/>
      <inertia ixx="0.1" ixy="0" ixz="0" iyy="0.1" iyz="0" izz="0.1"/>
    </inertial>
    <visual>
      <geometry>
        <mesh filename="package://boat_1/meshes/prop.stl"/>
      </geometry>
    </visual>
  </link>
  <link name="propeller_right">
    <inertial>
      <mass value="50"/>
      <inertia ixx="0.1" ixy="0" ixz="0" iyy="0.1" iyz="0" izz="0.1"/>
    </inertial>
    <visual>
      <geometry>
        <mesh filename="package://boat_1/meshes/prop.stl"/>
      </geometry>
    </visual>
  </link>
  <joint name="prop_joint_left" type="continuous">
    <parent link="hull_1"/>
    <child link="propeller_left"/>
    <origin xyz="-1.1 -0.5 -0.24"/>
    <axis xyz="1 0 0"/>
  </joint>
  <joint name="prop_joint_right" type="continuous">
    <parent link="hull_1"/>
    <child link="propeller_right"/>
    <origin xyz="-1.1 0.5 -0.24"/>
    <axis xyz="-1 0 0"/>
  </joint>

  <!-- GAZEBO -->
  <gazebo reference="hull_1">
    <velocity_decay>
      <linear>0.1</linear>
      <angular>50</angular>
    </velocity_decay>
  </gazebo>

  <!-- THRUSTER PLUGINS -->
  <gazebo>
    <plugin filename="libignition-gazebo-thruster-system.so" name="ignition::gazebo::systems::Thruster">
      <joint_name>prop_joint_left</joint_name>
      <thrust_coefficient>0.1</thrust_coefficient>
      <fluid_density>1000</fluid_density>
      <propeller_diameter>0.2</propeller_diameter>
      <velocity_control>true</velocity_control>
      <p_gain>0.1</p_gain>
    </plugin>
    <plugin filename="libignition-gazebo-thruster-system.so" name="ignition::gazebo::systems::Thruster">
      <joint_name>prop_joint_right</joint_name>
      <thrust_coefficient>0.1</thrust_coefficient>
      <fluid_density>1000</fluid_density>
      <propeller_diameter>0.2</propeller_diameter>
      <velocity_control>true</velocity_control>
      <p_gain>0.1</p_gain>
    </plugin>
  </gazebo>
  
  <!-- HYDRODYNAMICS -->
  <gazebo>
    <plugin filename="libignition-gazebo-hydrodynamics-system.so" name="ignition::gazebo::systems::Hydrodynamics">
      <link_name>hull_1</link_name>
      <linear_drag_coefficients>1 50 50</linear_drag_coefficients>
      <angular_drag_coefficients>5000 5000 5000</angular_drag_coefficients>
    </plugin>
  </gazebo>

  <!-- LIDAR SENSOR -->
  <gazebo reference="lidar_link">
    <sensor name="lidar_sensor" type="lidar">
      <topic>lidar_scan</topic>
      <update_rate>10</update_rate>
      <lidar>
        <horizontal_samples>360</horizontal_samples>
        <horizontal_resolution>1</horizontal_resolution>
        <horizontal_min_angle>-3.14159</horizontal_min_angle>
        <horizontal_max_angle>3.14159</horizontal_max_angle>
        <vertical_samples>1</vertical_samples>
        <range_min>0.2</range_min>
        <range_max>30.0</range_max>
      </lidar>
    </sensor>
  </gazebo>
</robot>