<?xml version="1.0"?>
<robot xmlns:xacro="http://www.ros.org/wiki/xacro" name="boat_1">

  <!-- PARAMETERS -->
  <xacro:property name="hull_mass" value="2000"/>
  <xacro:property name="prop_mass" value="50"/>
  <xacro:property name="ixx" value="5000"/>
  <xacro:property name="iyy" value="5000"/>
  <xacro:property name="izz" value="5000"/>

  <!-- HULL LINK -->
  <link name="hull_1">
    <inertial>
      <origin xyz="0.055 0 -0.5" rpy="0 0 0"/>
      <mass value="${hull_mass}"/>
      <inertia ixx="${ixx}" iyy="${iyy}" izz="${izz}" ixy="0" ixz="0" iyz="0"/>
    </inertial>
    <collision>
      <geometry>
        <box size="2 1.33 1.7"/>
      </geometry>
    </collision>
    <visual>
      <geometry>
        <mesh filename="package://boat_1/meshes/boat.stl"/>
      </geometry>
    </visual>
  </link>

  <!-- LiDAR LINK -->
  <link name="lidar_link">
    <inertial>
      <mass value="0.5"/>
      <inertia ixx="0.001" iyy="0.001" izz="0.001" ixy="0" ixz="0" iyz="0"/>
    </inertial>
    <visual>
      <geometry>
        <cylinder radius="0.12" length="0.15"/>
      </geometry>
      <material name="blue">
        <color rgba="0 0 1 1"/>
      </material>
    </visual>
    <collision>
      <geometry>
        <cylinder radius="0.12" length="0.15"/>
      </geometry>
    </collision>
  </link>
  <joint name="lidar_joint" type="fixed">
    <parent link="hull_1"/>
    <child link="lidar_link"/>
    <origin xyz="0.75 0.0 1.4" rpy="0 0 0"/>
  </joint>

  <!-- PROPELLERS -->
  <link name="propeller_left">
    <inertial>
      <mass value="${prop_mass}"/>
      <inertia ixx="0.1" iyy="0.1" izz="0.1" ixy="0" ixz="0" iyz="0"/>
    </inertial>
    <visual>
      <geometry>
        <mesh filename="package://boat_1/meshes/prop.stl"/>
      </geometry>
    </visual>
  </link>
  <link name="propeller_right">
    <inertial>
      <mass value="${prop_mass}"/>
      <inertia ixx="0.1" iyy="0.1" izz="0.1" ixy="0" ixz="0" iyz="0"/>
    </inertial>
    <visual>
      <geometry>
        <mesh filename="package://boat_1/meshes/prop.stl"/>
      </geometry>
    </visual>
  </link>
  <joint name="prop_joint_left" type="continuous">
    <parent link="hull_1"/>
    <child link="propeller_left"/>
    <origin xyz="-1.1 -0.5 -0.24"/>
    <axis xyz="1 0 0"/>
  </joint>
  <joint name="prop_joint_right" type="continuous">
    <parent link="hull_1"/>
    <child link="propeller_right"/>
    <origin xyz="-1.1 0.5 -0.24"/>
    <axis xyz="-1 0 0"/>
  </joint>

  <!-- GAZEBO -->
  <gazebo reference="hull_1">
    <velocity_decay>
      <linear>0.1</linear>
      <angular>50</angular>
    </velocity_decay>
  </gazebo>

  <!-- THRUSTER PLUGINS -->
  <gazebo>
    <plugin filename="libignition-gazebo-thruster-system.so"
            name="ignition::gazebo::systems::Thruster">
      <joint_name>prop_joint_left</joint_name>
      <thrust_coefficient>0.1</thrust_coefficient>
      <fluid_density>1000</fluid_density>
      <propeller_diameter>0.2</propeller_diameter>
      <velocity_control>true</velocity_control>
      <p_gain>0.1</p_gain>
    </plugin>
    <plugin filename="libignition-gazebo-thruster-system.so"
            name="ignition::gazebo::systems::Thruster">
      <joint_name>prop_joint_right</joint_name>
      <thrust_coefficient>0.1</thrust_coefficient>
      <fluid_density>1000</fluid_density>
      <propeller_diameter>0.2</propeller_diameter>
      <velocity_control>true</velocity_control>
      <p_gain>0.1</p_gain>
    </plugin>
  </gazebo>

  <!-- HYDRODYNAMICS -->
  <gazebo>
    <plugin filename="libignition-gazebo-hydrodynamics-system.so"
            name="ignition::gazebo::systems::Hydrodynamics">
      <link_name>hull_1</link_name>
      <linear_drag_coefficients>1 50 50</linear_drag_coefficients>
      <angular_drag_coefficients>5000 5000 5000</angular_drag_coefficients>
    </plugin>
  </gazebo>

  <!-- LIDAR SENSOR -->
  <gazebo reference="lidar_link">
    <sensor name="lidar_sensor" type="gpu_ray">
      <visualize>true</visualize>
      <update_rate>10</update_rate>
      <ray>
        <scan>
          <horizontal>
            <samples>360</samples>
            <min_angle>-3.14159</min_angle>
            <max_angle>3.14159</max_angle>
          </horizontal>
        </scan>
        <range>
          <min>0.2</min>
          <max>30.0</max>
        </range>
      </ray>
      <plugin name="lidar_pub" filename="libgazebo_ros_ray_sensor.so">
        <ros>
          <namespace>/boat_1</namespace>
          <remapping>scan:=scan</remapping>
        </ros>
        <frame_name>lidar_link</frame_name>
      </plugin>
    </sensor>
  </gazebo>
</robot>

