<?xml version="1.0" ?>
<!-- =================================================================================== -->
<!-- |    This document was autogenerated by xacro from /home/sharayu/ros2_ws/src/boat_1/xacro/boat_1.xacro | -->
<!-- |    EDITING THIS FILE BY HAND IS NOT RECOMMENDED                                 | -->
<!-- =================================================================================== -->
<robot name="boat_1">
  <!-- ================= PARAMETERS ================= -->
  <!-- ================= HULL ================= -->
  <link name="hull_1">
    <inertial>
      <origin rpy="0 0 0" xyz="0.055 0 -0.5"/>
      <mass value="2000"/>
      <inertia ixx="5000" ixy="0" ixz="0" iyy="5000" iyz="0" izz="5000"/>
    </inertial>
    <collision name="hull_collision">
      <geometry>
        <box size="2 1.33 1.7"/>
      </geometry>
    </collision>
    <collision name="stabilizer_left">
      <origin xyz="0 1 0"/>
      <geometry>
        <box size="1 0.1 0.1"/>
      </geometry>
    </collision>
    <collision name="stabilizer_right">
      <origin xyz="0 -1 0"/>
      <geometry>
        <box size="1 0.1 0.1"/>
      </geometry>
    </collision>
    <visual>
      <geometry>
        <mesh filename="package://boat_1/meshes/boat.stl"/>
      </geometry>
    </visual>
  </link>
  <!-- ================= LEFT PROPELLER ================= -->
  <link name="propeller_left">
    <inertial>
      <mass value="50"/>
      <inertia ixx="0.1" ixy="0" ixz="0" iyy="0.1" iyz="0" izz="0.1"/>
    </inertial>
    <visual>
      <geometry>
        <mesh filename="package://boat_1/meshes/prop.stl"/>
      </geometry>
    </visual>
  </link>
  <!-- ================= RIGHT PROPELLER ================= -->
  <link name="propeller_right">
    <inertial>
      <mass value="50"/>
      <inertia ixx="0.1" ixy="0" ixz="0" iyy="0.1" iyz="0" izz="0.1"/>
    </inertial>
    <visual>
      <geometry>
        <mesh filename="package://boat_1/meshes/prop.stl"/>
      </geometry>
    </visual>
  </link>
  <!-- ================= JOINTS ================= -->
  <joint name="prop_joint_left" type="continuous">
    <parent link="hull_1"/>
    <child link="propeller_left"/>
    <origin xyz="-1.1 -0.5 -0.24"/>
    <axis xyz="1 0 0"/>
  </joint>
  <joint name="prop_joint_right" type="continuous">
    <parent link="hull_1"/>
    <child link="propeller_right"/>
    <origin xyz="-1.1 0.5 -0.24"/>
    <axis xyz="-1 0 0"/>
  </joint>
  <!-- ================= GAZEBO EXTENSIONS ================= -->
  <gazebo reference="hull_1">
    <velocity_decay>
      <linear>0.1</linear>
      <angular>50.0</angular>
    </velocity_decay>
  </gazebo>
  <!-- ================= THRUSTERS ================= -->
  <gazebo>
    <plugin filename="libignition-gazebo-thruster-system.so" name="ignition::gazebo::systems::Thruster">
      <joint_name>prop_joint_left</joint_name>
      <thrust_coefficient>0.1</thrust_coefficient>
      <fluid_density>1000</fluid_density>
      <propeller_diameter>0.2</propeller_diameter>
      <velocity_control>true</velocity_control>
      <p_gain>0.1</p_gain>
    </plugin>
  </gazebo>
  <gazebo>
    <plugin filename="libignition-gazebo-thruster-system.so" name="ignition::gazebo::systems::Thruster">
      <joint_name>prop_joint_right</joint_name>
      <thrust_coefficient>0.1</thrust_coefficient>
      <fluid_density>1000</fluid_density>
      <propeller_diameter>0.2</propeller_diameter>
      <velocity_control>true</velocity_control>
      <p_gain>0.1</p_gain>
    </plugin>
  </gazebo>
  <!-- ================= HYDRODYNAMICS ================= -->
  <gazebo>
    <plugin filename="libignition-gazebo-hydrodynamics-system.so" name="ignition::gazebo::systems::Hydrodynamics">
      <link_name>hull_1</link_name>
      <linear_drag_coefficients>1 50 50</linear_drag_coefficients>
      <angular_drag_coefficients>5000 5000 5000</angular_drag_coefficients>
    </plugin>
  </gazebo>
</robot>
